<?xml version="1.0"?>

<robot xmlns:xacro="http://www.ros.org/wiki/xacro" name="my_robot">

<xacro:macro name="r_link" params="prefix parent length radius joint_rpy joint_xyz link_rpy link_xyz">

    <link name="${prefix}">
        <visual>
            <origin rpy="${link_rpy}" xyz="${link_xyz}"/> 
            <geometry>
                <cylinder length="${length}" radius="${radius}"/>
            </geometry>
        </visual>
        <inertial>
            <origin rpy="${link_rpy}" xyz="${link_xyz}"/> 
            <mass value="1"/>
            <inertia ixx="0.06" ixy="0.0" ixz="0.0" iyy="0.06" iyz="0.0" izz="0.25"/>
        </inertial>
    </link>


    <joint name="${parent}_to_${prefix}" type="continuous">
        <axis xyz="0 0 1"/>
        <parent link="${parent}"/>
        <child link="${prefix}"/>
        <origin rpy="${joint_rpy}" xyz="${joint_xyz}"/> 
        <limit effort="30" velocity="1.0"/>
        <dynamics damping="0.5" friction="0.0"/>
    </joint>


    <transmission name="${prefix}_transmission">
        <type>transmission_interface/SimpleTransmission</type>
        <actuator name="${prefix}_motor">
            <mechanicalReduction>1</mechanicalReduction>
        </actuator>
        <joint name="${parent}_to_${prefix}">
            <hardwareInterface>hardware_interface/PositionJointInterface</hardwareInterface>
        </joint>
    </transmission>


</xacro:macro>
</robot>

